<?xml version="1.0" encoding="UTF-8"?>
<sdf version="1.9">
  <model name="x3">
    <pose>0 0 0.053302 0 0 0</pose>
    <self_collide>false</self_collide>
    <static>false</static>

    <link name="base_link">
      <pose>0 0 0 0 0 0</pose>
      <inertial>
        <pose>0 0 0 0 0 0</pose>
        <mass>0.5</mass>
        <inertia>
          <ixx>0.0347563</ixx>
          <ixy>0</ixy>
          <ixz>0</ixz>
          <iyy>0.07</iyy>
          <iyz>0</iyz>
          <izz>0.0977</izz>
        </inertia>
      </inertial>

      <collision name="base_collision">
        <pose>0 0 0 0 0 0</pose>
        <geometry>
          <box>
            <size>0.47 0.47 0.11</size>
          </box>
        </geometry>
      </collision>

      <visual name="base_visual">
        <pose>0 0 0 0 0 0</pose>
        <geometry>
          <mesh>
            <scale>1 1 1</scale>
            <uri>model://x3/meshes/x3.dae</uri>
          </mesh>
        </geometry>
      </visual>

      <sensor name="imu_sensor" type="imu">
        <always_on>1</always_on>
        <update_rate>250</update_rate>
      </sensor>

      <sensor name="magnetometer_sensor" type="magnetometer">
        <always_on>1</always_on>
        <update_rate>100</update_rate>
      </sensor>

      <sensor name="air_pressure_sensor" type="air_pressure">
        <always_on>1</always_on>
        <update_rate>50</update_rate>
      </sensor>

      <sensor name="navsat_sensor" type="navsat">
        <always_on>1</always_on>
        <update_rate>30</update_rate>
      </sensor>
    </link>

    <link name="rotor_0">
      <pose>0.13 -0.22 0.023 0 0 0</pose>
      <inertial>
        <pose>0 0 0 0 0 0</pose>
        <mass>0.005</mass>
        <inertia>
          <ixx>9.75e-07</ixx>
          <ixy>0</ixy>
          <ixz>0</ixz>
          <iyy>4.17041e-05</iyy>
          <iyz>0</iyz>
          <izz>4.26041e-05</izz>
        </inertia>
      </inertial>
      <collision name="rotor_0_collision">
        <pose>0 0 0 0 0 0</pose>
        <geometry>
          <cylinder>
            <length>0.005</length>
            <radius>0.1</radius>
          </cylinder>
        </geometry>
      </collision>
      <visual name="rotor_0_visual">
        <pose>0 0 0 0 0 0</pose>
        <geometry>
          <mesh>
            <scale>0.1 0.1 0.1</scale>
            <uri>model://x3/meshes/propeller_ccw.dae</uri>
          </mesh>
        </geometry>
      </visual>
    </link>

    <joint name="rotor_0_joint" type="revolute">
      <parent>base_link</parent>
      <child>rotor_0</child>
      <axis>
        <xyz>0 0 1</xyz>
        <limit>
          <lower>-1e16</lower>
          <upper>1e16</upper>
        </limit>
      </axis>
    </joint>

    <link name="rotor_1">
      <pose>-0.13 0.2 0.023 0 0 0</pose>
      <inertial>
        <pose>0 0 0 0 0 0</pose>
        <mass>0.005</mass>
        <inertia>
          <ixx>9.75e-07</ixx>
          <ixy>0</ixy>
          <ixz>0</ixz>
          <iyy>4.17041e-05</iyy>
          <iyz>0</iyz>
          <izz>4.26041e-05</izz>
        </inertia>
      </inertial>
      <collision name="rotor_1_collision">
        <pose>0 0 0 0 0 0</pose>
        <geometry>
          <cylinder>
            <length>0.005</length>
            <radius>0.1</radius>
          </cylinder>
        </geometry>
      </collision>
      <visual name="rotor_1_visual">
        <pose>0 0 0 0 0 0</pose>
        <geometry>
          <mesh>
            <scale>0.1 0.1 0.1</scale>
            <uri>model://x3/meshes/propeller_ccw.dae</uri>
          </mesh>
        </geometry>
      </visual>
    </link>

    <joint name="rotor_1_joint" type="revolute">
      <parent>base_link</parent>
      <child>rotor_1</child>
      <axis>
        <xyz>0 0 1</xyz>
        <limit>
          <lower>-1e16</lower>
          <upper>1e16</upper>
        </limit>
      </axis>
    </joint>

    <link name="rotor_2">
      <pose>0.13 0.22 0.023 0 0 0</pose>
      <inertial>
        <pose>0 0 0 0 0 0</pose>
        <mass>0.005</mass>
        <inertia>
          <ixx>9.75e-07</ixx>
          <ixy>0</ixy>
          <ixz>0</ixz>
          <iyy>4.17041e-05</iyy>
          <iyz>0</iyz>
          <izz>4.26041e-05</izz>
        </inertia>
      </inertial>
      <collision name="rotor_2_collision">
        <pose>0 0 0 0 0 0</pose>
        <geometry>
          <cylinder>
            <length>0.005</length>
            <radius>0.1</radius>
          </cylinder>
        </geometry>
      </collision>
      <visual name="rotor_2_visual">
        <pose>0 0 0 0 0 0</pose>
        <geometry>
          <mesh>
            <scale>0.1 0.1 0.1</scale>
            <uri>model://x3/meshes/propeller_cw.dae</uri>
          </mesh>
        </geometry>
      </visual>
    </link>

    <joint name="rotor_2_joint" type="revolute">
      <parent>base_link</parent>
      <child>rotor_2</child>
      <axis>
        <xyz>0 0 1</xyz>
        <limit>
          <lower>-1e16</lower>
          <upper>1e16</upper>
        </limit>
      </axis>
    </joint>

    <link name="rotor_3">
      <pose>-0.13 -0.2 0.023 0 0 0</pose>
      <inertial>
        <pose>0 0 0 0 0 0</pose>
        <mass>0.005</mass>
        <inertia>
          <ixx>9.75e-07</ixx>
          <ixy>0</ixy>
          <ixz>0</ixz>
          <iyy>4.17041e-05</iyy>
          <iyz>0</iyz>
          <izz>4.26041e-05</izz>
        </inertia>
      </inertial>
      <collision name="rotor_3_collision">
        <pose>0 0 0 0 0 0</pose>
        <geometry>
          <cylinder>
            <length>0.005</length>
            <radius>0.1</radius>
          </cylinder>
        </geometry>
      </collision>
      <visual name="rotor_3_visual">
        <pose>0 0 0 0 0 0</pose>
        <geometry>
          <mesh>
            <scale>0.1 0.1 0.1</scale>
            <uri>model://x3/meshes/propeller_cw.dae</uri>
          </mesh>
        </geometry>
      </visual>
    </link>

    <joint name="rotor_3_joint" type="revolute">
      <parent>base_link</parent>
      <child>rotor_3</child>
      <axis>
        <xyz>0 0 1</xyz>
        <limit>
          <lower>-1e16</lower>
          <upper>1e16</upper>
        </limit>
      </axis>
    </joint>

  </model>
</sdf>
