<?xml version="1.0" encoding="UTF-8"?>
<sdf version="1.9">
  <model name="gz_x500_base">
    <pose>0 0 0.25 0 0 0</pose>
    <self_collide>false</self_collide>
    <static>false</static>

    <plugin filename="gz-sim-odometry-publisher-system" name="gz::sim::systems::OdometryPublisher">
      <dimensions>3</dimensions>
    </plugin>

    <link name="base_link">
      <pose>0 0 0 0 0 0</pose>
      <inertial>
        <mass>1.8</mass>
        <inertia>
          <ixx>0.021</ixx>
          <ixy>0.0</ixy>
          <ixz>0.0</ixz>
          <iyy>0.021</iyy>
          <iyz>0.0</iyz>
          <izz>0.040</izz>
        </inertia>
      </inertial>

      <collision name="base_collision">
        <geometry>
          <box>
            <size>0.35 0.35 0.06</size>
          </box>
        </geometry>
      </collision>

      <visual name="base_visual">
        <geometry>
          <box>
            <size>0.35 0.35 0.06</size>
          </box>
        </geometry>
        <material>
          <ambient>0.1 0.1 0.1 1</ambient>
          <diffuse>0.1 0.1 0.1 1</diffuse>
          <specular>0.02 0.02 0.02 1</specular>
        </material>
      </visual>

      <sensor name="air_pressure_sensor" type="air_pressure">
        <always_on>1</always_on>
        <update_rate>50</update_rate>
      </sensor>

      <sensor name="magnetometer_sensor" type="magnetometer">
        <always_on>1</always_on>
        <update_rate>100</update_rate>
      </sensor>

      <sensor name="imu_sensor" type="imu">
        <always_on>1</always_on>
        <update_rate>250</update_rate>
      </sensor>

      <sensor name="navsat_sensor" type="navsat">
        <always_on>1</always_on>
        <update_rate>30</update_rate>
      </sensor>
    </link>

    <link name="rotor_0">
      <pose>0.18 -0.18 0.03 0 0 0</pose>
      <inertial>
        <mass>0.02</mass>
        <inertia>
          <ixx>0.00001</ixx>
          <iyy>0.00001</iyy>
          <izz>0.00002</izz>
        </inertia>
      </inertial>
      <visual name="rotor_0_visual">
        <geometry>
          <cylinder>
            <radius>0.08</radius>
            <length>0.01</length>
          </cylinder>
        </geometry>
      </visual>
    </link>

    <joint name="rotor_0_joint" type="revolute">
      <parent>base_link</parent>
      <child>rotor_0</child>
      <axis>
        <xyz>0 0 1</xyz>
        <limit>
          <lower>-1e16</lower>
          <upper>1e16</upper>
        </limit>
      </axis>
    </joint>

    <link name="rotor_1">
      <pose>-0.18 0.18 0.03 0 0 0</pose>
      <inertial>
        <mass>0.02</mass>
        <inertia>
          <ixx>0.00001</ixx>
          <iyy>0.00001</iyy>
          <izz>0.00002</izz>
        </inertia>
      </inertial>
      <visual name="rotor_1_visual">
        <geometry>
          <cylinder>
            <radius>0.08</radius>
            <length>0.01</length>
          </cylinder>
        </geometry>
      </visual>
    </link>

    <joint name="rotor_1_joint" type="revolute">
      <parent>base_link</parent>
      <child>rotor_1</child>
      <axis>
        <xyz>0 0 1</xyz>
        <limit>
          <lower>-1e16</lower>
          <upper>1e16</upper>
        </limit>
      </axis>
    </joint>

    <link name="rotor_2">
      <pose>0.18 0.18 0.03 0 0 0</pose>
      <inertial>
        <mass>0.02</mass>
        <inertia>
          <ixx>0.00001</ixx>
          <iyy>0.00001</iyy>
          <izz>0.00002</izz>
        </inertia>
      </inertial>
      <visual name="rotor_2_visual">
        <geometry>
          <cylinder>
            <radius>0.08</radius>
            <length>0.01</length>
          </cylinder>
        </geometry>
      </visual>
    </link>

    <joint name="rotor_2_joint" type="revolute">
      <parent>base_link</parent>
      <child>rotor_2</child>
      <axis>
        <xyz>0 0 1</xyz>
        <limit>
          <lower>-1e16</lower>
          <upper>1e16</upper>
        </limit>
      </axis>
    </joint>

    <link name="rotor_3">
      <pose>-0.18 -0.18 0.03 0 0 0</pose>
      <inertial>
        <mass>0.02</mass>
        <inertia>
          <ixx>0.00001</ixx>
          <iyy>0.00001</iyy>
          <izz>0.00002</izz>
        </inertia>
      </inertial>
      <visual name="rotor_3_visual">
        <geometry>
          <cylinder>
            <radius>0.08</radius>
            <length>0.01</length>
          </cylinder>
        </geometry>
      </visual>
    </link>

    <joint name="rotor_3_joint" type="revolute">
      <parent>base_link</parent>
      <child>rotor_3</child>
      <axis>
        <xyz>0 0 1</xyz>
        <limit>
          <lower>-1e16</lower>
          <upper>1e16</upper>
        </limit>
      </axis>
    </joint>

    <plugin filename="gz-sim-multicopter-motor-model-system" name="gz::sim::systems::MulticopterMotorModel">
      <jointName>rotor_0_joint</jointName>
      <linkName>rotor_0</linkName>
      <turningDirection>ccw</turningDirection>
      <timeConstantUp>0.0125</timeConstantUp>
      <timeConstantDown>0.025</timeConstantDown>
      <maxRotVelocity>1000.0</maxRotVelocity>
      <motorConstant>8.54858e-06</motorConstant>
      <momentConstant>0.016</momentConstant>
      <commandSubTopic>command/motor_speed</commandSubTopic>
      <motorNumber>0</motorNumber>
      <rotorDragCoefficient>8.06428e-05</rotorDragCoefficient>
      <rollingMomentCoefficient>1e-06</rollingMomentCoefficient>
      <rotorVelocitySlowdownSim>10</rotorVelocitySlowdownSim>
      <motorType>velocity</motorType>
    </plugin>

    <plugin filename="gz-sim-multicopter-motor-model-system" name="gz::sim::systems::MulticopterMotorModel">
      <jointName>rotor_1_joint</jointName>
      <linkName>rotor_1</linkName>
      <turningDirection>ccw</turningDirection>
      <timeConstantUp>0.0125</timeConstantUp>
      <timeConstantDown>0.025</timeConstantDown>
      <maxRotVelocity>1000.0</maxRotVelocity>
      <motorConstant>8.54858e-06</motorConstant>
      <momentConstant>0.016</momentConstant>
      <commandSubTopic>command/motor_speed</commandSubTopic>
      <motorNumber>1</motorNumber>
      <rotorDragCoefficient>8.06428e-05</rotorDragCoefficient>
      <rollingMomentCoefficient>1e-06</rollingMomentCoefficient>
      <rotorVelocitySlowdownSim>10</rotorVelocitySlowdownSim>
      <motorType>velocity</motorType>
    </plugin>

    <plugin filename="gz-sim-multicopter-motor-model-system" name="gz::sim::systems::MulticopterMotorModel">
      <jointName>rotor_2_joint</jointName>
      <linkName>rotor_2</linkName>
      <turningDirection>cw</turningDirection>
      <timeConstantUp>0.0125</timeConstantUp>
      <timeConstantDown>0.025</timeConstantDown>
      <maxRotVelocity>1000.0</maxRotVelocity>
      <motorConstant>8.54858e-06</motorConstant>
      <momentConstant>0.016</momentConstant>
      <commandSubTopic>command/motor_speed</commandSubTopic>
      <motorNumber>2</motorNumber>
      <rotorDragCoefficient>8.06428e-05</rotorDragCoefficient>
      <rollingMomentCoefficient>1e-06</rollingMomentCoefficient>
      <rotorVelocitySlowdownSim>10</rotorVelocitySlowdownSim>
      <motorType>velocity</motorType>
    </plugin>

    <plugin filename="gz-sim-multicopter-motor-model-system" name="gz::sim::systems::MulticopterMotorModel">
      <jointName>rotor_3_joint</jointName>
      <linkName>rotor_3</linkName>
      <turningDirection>cw</turningDirection>
      <timeConstantUp>0.0125</timeConstantUp>
      <timeConstantDown>0.025</timeConstantDown>
      <maxRotVelocity>1000.0</maxRotVelocity>
      <motorConstant>8.54858e-06</motorConstant>
      <momentConstant>0.016</momentConstant>
      <commandSubTopic>command/motor_speed</commandSubTopic>
      <motorNumber>3</motorNumber>
      <rotorDragCoefficient>8.06428e-05</rotorDragCoefficient>
      <rollingMomentCoefficient>1e-06</rollingMomentCoefficient>
      <rotorVelocitySlowdownSim>10</rotorVelocitySlowdownSim>
      <motorType>velocity</motorType>
    </plugin>
  </model>
</sdf>
